<sdf version='1.6'>
  <model name='go2'>
    <link name='base'>
      <pose frame=''>0 0 0 0 -0 0</pose>
      <inertial>
        <pose frame=''>0.020317 0 -0.00156 0 -0 0</pose>
        <mass>7.192</mass>
        <inertia>
          <ixx>0.0275133</ixx>
          <ixy>0.00012166</ixy>
          <ixz>0.00204105</ixz>
          <iyy>0.101227</iyy>
          <iyz>-3.12e-05</iyz>
          <izz>0.107378</izz>
        </inertia>
      </inertial>
      <collision name='base_fixed_joint_lump__trunk_collision'>
        <pose frame=''>0 0 0 0 -0 0</pose>
        <geometry>
          <box>
            <size>0.3762 0.0935 0.114</size>
          </box>
        </geometry>
        <surface>
          <contact>
            <ode>
              <kp>1e+06</kp>
              <kd>1</kd>
            </ode>
          </contact>
          <friction>
            <ode>
              <mu>0.2</mu>
              <mu2>0.2</mu2>
            </ode>
          </friction>
        </surface>
      </collision>
      <collision name='base_fixed_joint_lump__hokuyo_frame_collision_1'>
        <pose frame=''>0 0 0.0845 0 -0 0</pose>
        <geometry>
          <box>
            <size>0.058 0.058 0.087</size>
          </box>
        </geometry>
        <surface>
          <contact>
            <ode/>
          </contact>
          <friction>
            <ode/>
          </friction>
        </surface>
      </collision>
      <collision name='base_fixed_joint_lump__imu_link_collision_2'>
        <pose frame=''>0 0 0 0 -0 0</pose>
        <geometry>
          <box>
            <size>0.001 0.001 0.001</size>
          </box>
        </geometry>
        <surface>
          <contact>
            <ode/>
          </contact>
          <friction>
            <ode>
              <mu>0.2</mu>
              <mu2>0.2</mu2>
            </ode>
          </friction>
        </surface>
      </collision>
      <visual name='base_visual'>
        <pose frame=''>0 0 0 0 -0 0</pose>
        <geometry>
          <box>
            <size>0.001 0.001 0.001</size>
          </box>
        </geometry>
        <material>
          <script>
            <uri>__default__</uri>
            <name>__default__</name>
          </script>
        </material>
      </visual>
      <visual name='base_fixed_joint_lump__trunk_visual_1'>
        <pose frame=''>0 0 0 0 -0 0</pose>
        <geometry>
          <mesh>
            <scale>1 1 1</scale>
            <uri>model://go2_description/meshes/trunk.dae</uri>
          </mesh>
        </geometry>
        <material>
          <script>
            <uri>__default__</uri>
            <name>__default__</name>
          </script>
        </material>
      </visual>
      <visual name='base_fixed_joint_lump__hokuyo_frame_visual_2'>
        <pose frame=''>0 0 0.096 0 -0 0</pose>
        <geometry>
          <mesh>
            <scale>1 1 1</scale>
            <uri>model://hector_sensors_description/meshes/hokuyo_utm30lx/hokuyo_utm_30lx.dae</uri>
          </mesh>
        </geometry>
        <material>
          <script>
            <uri>__default__</uri>
            <name>__default__</name>
          </script>
        </material>
      </visual>
      <visual name='base_fixed_joint_lump__imu_link_visual_3'>
        <pose frame=''>0 0 0 0 -0 0</pose>
        <geometry>
          <box>
            <size>0.001 0.001 0.001</size>
          </box>
        </geometry>
        <material>
          <script>
            <uri>__default__</uri>
            <name>__default__</name>
          </script>
        </material>
      </visual>
      <velocity_decay/>
      <velocity_decay/>
      <velocity_decay/>
      <sensor name='hokuyo' type='ray'>
        <always_on>1</always_on>
        <update_rate>30</update_rate>
        <visualize>0</visualize>
        <ray>
          <scan>
            <horizontal>
              <samples>1040</samples>
              <resolution>1</resolution>
              <min_angle>2.26893</min_angle>
              <max_angle>-2.26893</max_angle>
            </horizontal>
          </scan>
          <range>
            <min>0.2</min>
            <max>30</max>
            <resolution>0.01</resolution>
          </range>
          <noise>
            <type>gaussian</type>
            <mean>0</mean>
            <stddev>0.004</stddev>
          </noise>
        </ray>
        <plugin name='gazebo_ros_hokuyo_controller' filename='libgazebo_ros_laser.so'>
          <topicName>scan</topicName>
          <frameName>hokuyo_frame</frameName>
        </plugin>
        <pose frame=''>0 0 0.096 0 -0 0</pose>
      </sensor>
      <velocity_decay/>
      <gravity>1</gravity>
      <sensor name='imu_sensor' type='imu'>
        <always_on>1</always_on>
        <update_rate>1000</update_rate>
        <visualize>1</visualize>
        <topic>__default_topic__</topic>
        <plugin name='imu_plugin' filename='libgazebo_ros_imu_sensor.so'>
          <topicName>trunk_imu</topicName>
          <bodyName>imu_link</bodyName>
          <updateRateHZ>1000.0</updateRateHZ>
          <gaussianNoise>0.0</gaussianNoise>
          <xyzOffset>0 0 0</xyzOffset>
          <rpyOffset>0 0 0</rpyOffset>
          <frameName>imu_link</frameName>
        </plugin>
        <pose frame=''>0 0 0 0 -0 0</pose>
      </sensor>
      <gravity>1</gravity>
      <velocity_decay/>
    </link>
    <link name='FL_hip'>
      <pose frame=''>0.1934 0.0465 0 0 -0 0</pose>
      <inertial>
        <pose frame=''>-0.0054 0.00194 -0.000105 0 -0 0</pose>
        <mass>0.678</mass>
        <inertia>
          <ixx>0.00048</ixx>
          <ixy>-3.01e-06</ixy>
          <ixz>1.11e-06</ixz>
          <iyy>0.000884</iyy>
          <iyz>-1.42e-06</iyz>
          <izz>0.000596</izz>
        </inertia>
      </inertial>
      <collision name='FL_hip_collision'>
        <pose frame=''>0 0.0955 0 1.5708 -0 0</pose>
        <geometry>
          <cylinder>
            <length>0.04</length>
            <radius>0.046</radius>
          </cylinder>
        </geometry>
        <surface>
          <contact>
            <ode/>
          </contact>
          <friction>
            <ode>
              <mu>0.2</mu>
              <mu2>0.2</mu2>
            </ode>
          </friction>
        </surface>
      </collision>
      <visual name='FL_hip_visual'>
        <pose frame=''>0 0 0 0 -0 0</pose>
        <geometry>
          <mesh>
            <scale>1 1 1</scale>
            <uri>model://go2_description/meshes/hip.dae</uri>
          </mesh>
        </geometry>
        <material>
          <script>
            <uri>__default__</uri>
            <name>__default__</name>
          </script>
        </material>
      </visual>
      <gravity>1</gravity>
      <velocity_decay/>
    </link>
    <joint name='FL_hip_joint' type='revolute'>
      <child>FL_hip</child>
      <parent>base</parent>
      <axis>
        <xyz>1 0 0</xyz>
        <limit>
          <lower>-1.0472</lower>
          <upper>1.0472</upper>
          <effort>23.7</effort>
          <velocity>30.1</velocity>
        </limit>
        <dynamics>
          <damping>0.01</damping>
          <friction>0.2</friction>
          <spring_reference>0</spring_reference>
          <spring_stiffness>0</spring_stiffness>
        </dynamics>
        <use_parent_model_frame>1</use_parent_model_frame>
      </axis>
    </joint>
    <link name='FL_thigh'>
      <pose frame=''>0.1934 0.142 0 0 -0 0</pose>
      <inertial>
        <pose frame=''>-0.00374 -0.0223 -0.0327 0 -0 0</pose>
        <mass>1.152</mass>
        <inertia>
          <ixx>0.00584</ixx>
          <ixy>8.72e-05</ixy>
          <ixz>-0.000289</ixz>
          <iyy>0.0058</iyy>
          <iyz>0.000808</iyz>
          <izz>0.00103</izz>
        </inertia>
      </inertial>
      <collision name='FL_thigh_collision'>
        <pose frame=''>0 0 -0.1065 3.14159 1.57079 3.14159</pose>
        <geometry>
          <box>
            <size>0.213 0.0245 0.034</size>
          </box>
        </geometry>
        <surface>
          <contact>
            <ode>
              <kp>1e+06</kp>
              <kd>1</kd>
            </ode>
          </contact>
          <friction>
            <ode>
              <mu>0.2</mu>
              <mu2>0.2</mu2>
            </ode>
          </friction>
        </surface>
      </collision>
      <visual name='FL_thigh_visual'>
        <pose frame=''>0 0 0 0 -0 0</pose>
        <geometry>
          <mesh>
            <scale>1 1 1</scale>
            <uri>model://go2_description/meshes/thigh.dae</uri>
          </mesh>
        </geometry>
        <material>
          <script>
            <uri>__default__</uri>
            <name>__default__</name>
          </script>
        </material>
      </visual>
      <gravity>1</gravity>
      <velocity_decay/>
      <self_collide>1</self_collide>
    </link>
    <joint name='FL_thigh_joint' type='revolute'>
      <child>FL_thigh</child>
      <parent>FL_hip</parent>
      <axis>
        <xyz>0 1 0</xyz>
        <limit>
          <lower>-1.5708</lower>
          <upper>3.4907</upper>
          <effort>23.7</effort>
          <velocity>30.1</velocity>
        </limit>
        <dynamics>
          <damping>0.01</damping>
          <friction>0.2</friction>
          <spring_reference>0</spring_reference>
          <spring_stiffness>0</spring_stiffness>
        </dynamics>
        <use_parent_model_frame>1</use_parent_model_frame>
      </axis>
    </joint>
    <link name='FL_calf'>
      <pose frame=''>0.1934 0.142 -0.213 0 -0 0</pose>
      <inertial>
        <pose frame=''>0.003944 -0.000702 -0.142477 0 -0 0</pose>
        <mass>0.214</mass>
        <inertia>
          <ixx>0.00150432</ixx>
          <ixy>5.70698e-07</ixy>
          <ixz>-5.98808e-06</ixz>
          <iyy>0.00152557</iyy>
          <iyz>1.24056e-05</iyz>
          <izz>4.38377e-05</izz>
        </inertia>
      </inertial>
      <collision name='FL_calf_collision'>
        <pose frame=''>0 0 -0.1065 3.14159 1.57079 3.14159</pose>
        <geometry>
          <box>
            <size>0.213 0.016 0.016</size>
          </box>
        </geometry>
        <surface>
          <contact>
            <ode/>
          </contact>
          <friction>
            <ode>
              <mu>0.2</mu>
              <mu2>0.2</mu2>
            </ode>
          </friction>
        </surface>
      </collision>
      <collision name='FL_calf_fixed_joint_lump__FL_foot_collision_1'>
        <pose frame=''>0 0 -0.213 0 -0 0</pose>
        <geometry>
          <sphere>
            <radius>0.02</radius>
          </sphere>
        </geometry>
        <surface>
          <contact>
            <ode>
              <kp>1e+06</kp>
              <kd>1</kd>
            </ode>
          </contact>
          <friction>
            <ode>
              <mu>0.6</mu>
              <mu2>0.6</mu2>
            </ode>
          </friction>
        </surface>
      </collision>
      <visual name='FL_calf_visual'>
        <pose frame=''>0 0 0 0 -0 0</pose>
        <geometry>
          <mesh>
            <scale>1 1 1</scale>
            <uri>model://go2_description/meshes/calf.dae</uri>
          </mesh>
        </geometry>
        <material>
          <script>
            <uri>__default__</uri>
            <name>__default__</name>
          </script>
        </material>
      </visual>
      <visual name='FL_calf_fixed_joint_lump__FL_foot_visual_1'>
        <pose frame=''>0 0 -0.213 0 -0 0</pose>
        <geometry>
          <sphere>
            <radius>0.01</radius>
          </sphere>
        </geometry>
        <plugin name='drawForcePlugin' filename='libunitreeDrawForcePlugin.so'>
          <topicName>FL_foot_contact</topicName>
        </plugin>
        <material>
          <script>
            <uri>__default__</uri>
            <name>__default__</name>
          </script>
        </material>
      </visual>
      <velocity_decay/>
      <sensor name='FL_foot_contact' type='contact'>
        <update_rate>100</update_rate>
        <plugin name='contactPlugin' filename='libunitreeFootContactPlugin.so'/>
        <contact>
          <collision>FL_calf_fixed_joint_lump__FL_foot_collision_1</collision>
          <topic>__default_topic__</topic>
        </contact>
      </sensor>
      <velocity_decay/>
      <self_collide>1</self_collide>
      <velocity_decay/>
      <gravity>1</gravity>
      <velocity_decay/>
      <self_collide>1</self_collide>
    </link>
    <joint name='FL_calf_joint' type='revolute'>
      <child>FL_calf</child>
      <parent>FL_thigh</parent>
      <axis>
        <xyz>0 1 0</xyz>
        <limit>
          <lower>-2.7227</lower>
          <upper>-0.83776</upper>
          <effort>35.55</effort>
          <velocity>20.06</velocity>
        </limit>
        <dynamics>
          <damping>0.01</damping>
          <friction>0.2</friction>
          <spring_reference>0</spring_reference>
          <spring_stiffness>0</spring_stiffness>
        </dynamics>
        <use_parent_model_frame>1</use_parent_model_frame>
      </axis>
    </joint>
    <link name='FR_hip'>
      <pose frame=''>0.1934 -0.0465 0 0 -0 0</pose>
      <inertial>
        <pose frame=''>-0.0054 -0.00194 -0.000105 0 -0 0</pose>
        <mass>0.678</mass>
        <inertia>
          <ixx>0.00048</ixx>
          <ixy>3.01e-06</ixy>
          <ixz>1.11e-06</ixz>
          <iyy>0.000884</iyy>
          <iyz>1.42e-06</iyz>
          <izz>0.000596</izz>
        </inertia>
      </inertial>
      <collision name='FR_hip_collision'>
        <pose frame=''>0 -0.0955 0 1.5708 -0 0</pose>
        <geometry>
          <cylinder>
            <length>0.04</length>
            <radius>0.046</radius>
          </cylinder>
        </geometry>
        <surface>
          <contact>
            <ode/>
          </contact>
          <friction>
            <ode>
              <mu>0.2</mu>
              <mu2>0.2</mu2>
            </ode>
          </friction>
        </surface>
      </collision>
      <visual name='FR_hip_visual'>
        <pose frame=''>0 0 0 3.14159 -0 0</pose>
        <geometry>
          <mesh>
            <scale>1 1 1</scale>
            <uri>model://go2_description/meshes/hip.dae</uri>
          </mesh>
        </geometry>
        <material>
          <script>
            <uri>__default__</uri>
            <name>__default__</name>
          </script>
        </material>
      </visual>
      <gravity>1</gravity>
      <velocity_decay/>
    </link>
    <joint name='FR_hip_joint' type='revolute'>
      <child>FR_hip</child>
      <parent>base</parent>
      <axis>
        <xyz>1 0 0</xyz>
        <limit>
          <lower>-1.0472</lower>
          <upper>1.0472</upper>
          <effort>23.7</effort>
          <velocity>30.1</velocity>
        </limit>
        <dynamics>
          <damping>0.01</damping>
          <friction>0.2</friction>
          <spring_reference>0</spring_reference>
          <spring_stiffness>0</spring_stiffness>
        </dynamics>
        <use_parent_model_frame>1</use_parent_model_frame>
      </axis>
    </joint>
    <link name='FR_thigh'>
      <pose frame=''>0.1934 -0.142 0 0 -0 0</pose>
      <inertial>
        <pose frame=''>-0.00374 0.0223 -0.0327 0 -0 0</pose>
        <mass>1.152</mass>
        <inertia>
          <ixx>0.00584</ixx>
          <ixy>-8.72e-05</ixy>
          <ixz>-0.000289</ixz>
          <iyy>0.0058</iyy>
          <iyz>-0.000808</iyz>
          <izz>0.00103</izz>
        </inertia>
      </inertial>
      <collision name='FR_thigh_collision'>
        <pose frame=''>0 0 -0.1065 3.14159 1.57079 3.14159</pose>
        <geometry>
          <box>
            <size>0.213 0.0245 0.034</size>
          </box>
        </geometry>
        <surface>
          <contact>
            <ode>
              <kp>1e+06</kp>
              <kd>1</kd>
            </ode>
          </contact>
          <friction>
            <ode>
              <mu>0.2</mu>
              <mu2>0.2</mu2>
            </ode>
          </friction>
        </surface>
      </collision>
      <visual name='FR_thigh_visual'>
        <pose frame=''>0 0 0 0 -0 0</pose>
        <geometry>
          <mesh>
            <scale>1 1 1</scale>
            <uri>model://go2_description/meshes/thigh_mirror.dae</uri>
          </mesh>
        </geometry>
        <material>
          <script>
            <uri>__default__</uri>
            <name>__default__</name>
          </script>
        </material>
      </visual>
      <gravity>1</gravity>
      <velocity_decay/>
      <self_collide>1</self_collide>
    </link>
    <joint name='FR_thigh_joint' type='revolute'>
      <child>FR_thigh</child>
      <parent>FR_hip</parent>
      <axis>
        <xyz>0 1 0</xyz>
        <limit>
          <lower>-1.5708</lower>
          <upper>3.4907</upper>
          <effort>23.7</effort>
          <velocity>30.1</velocity>
        </limit>
        <dynamics>
          <damping>0.01</damping>
          <friction>0.2</friction>
          <spring_reference>0</spring_reference>
          <spring_stiffness>0</spring_stiffness>
        </dynamics>
        <use_parent_model_frame>1</use_parent_model_frame>
      </axis>
    </joint>
    <link name='FR_calf'>
      <pose frame=''>0.1934 -0.142 -0.213 0 -0 0</pose>
      <inertial>
        <pose frame=''>0.003944 -0.000702 -0.142477 0 -0 0</pose>
        <mass>0.214</mass>
        <inertia>
          <ixx>0.00150432</ixx>
          <ixy>5.70698e-07</ixy>
          <ixz>-5.98808e-06</ixz>
          <iyy>0.00152557</iyy>
          <iyz>1.24056e-05</iyz>
          <izz>4.38377e-05</izz>
        </inertia>
      </inertial>
      <collision name='FR_calf_collision'>
        <pose frame=''>0 0 -0.1065 3.14159 1.57079 3.14159</pose>
        <geometry>
          <box>
            <size>0.213 0.016 0.016</size>
          </box>
        </geometry>
        <surface>
          <contact>
            <ode/>
          </contact>
          <friction>
            <ode>
              <mu>0.2</mu>
              <mu2>0.2</mu2>
            </ode>
          </friction>
        </surface>
      </collision>
      <collision name='FR_calf_fixed_joint_lump__FR_foot_collision_1'>
        <pose frame=''>0 0 -0.213 0 -0 0</pose>
        <geometry>
          <sphere>
            <radius>0.02</radius>
          </sphere>
        </geometry>
        <surface>
          <contact>
            <ode>
              <kp>1e+06</kp>
              <kd>1</kd>
            </ode>
          </contact>
          <friction>
            <ode>
              <mu>0.6</mu>
              <mu2>0.6</mu2>
            </ode>
          </friction>
        </surface>
      </collision>
      <visual name='FR_calf_visual'>
        <pose frame=''>0 0 0 0 -0 0</pose>
        <geometry>
          <mesh>
            <scale>1 1 1</scale>
            <uri>model://go2_description/meshes/calf.dae</uri>
          </mesh>
        </geometry>
        <material>
          <script>
            <uri>__default__</uri>
            <name>__default__</name>
          </script>
        </material>
      </visual>
      <visual name='FR_calf_fixed_joint_lump__FR_foot_visual_1'>
        <pose frame=''>0 0 -0.213 0 -0 0</pose>
        <geometry>
          <sphere>
            <radius>0.01</radius>
          </sphere>
        </geometry>
        <plugin name='drawForcePlugin' filename='libunitreeDrawForcePlugin.so'>
          <topicName>FR_foot_contact</topicName>
        </plugin>
        <material>
          <script>
            <uri>__default__</uri>
            <name>__default__</name>
          </script>
        </material>
      </visual>
      <velocity_decay/>
      <sensor name='FR_foot_contact' type='contact'>
        <update_rate>100</update_rate>
        <plugin name='contactPlugin' filename='libunitreeFootContactPlugin.so'/>
        <contact>
          <collision>FR_calf_fixed_joint_lump__FR_foot_collision_1</collision>
          <topic>__default_topic__</topic>
        </contact>
      </sensor>
      <velocity_decay/>
      <self_collide>1</self_collide>
      <velocity_decay/>
      <gravity>1</gravity>
      <velocity_decay/>
      <self_collide>1</self_collide>
    </link>
    <joint name='FR_calf_joint' type='revolute'>
      <child>FR_calf</child>
      <parent>FR_thigh</parent>
      <axis>
        <xyz>0 1 0</xyz>
        <limit>
          <lower>-2.7227</lower>
          <upper>-0.83776</upper>
          <effort>35.55</effort>
          <velocity>20.06</velocity>
        </limit>
        <dynamics>
          <damping>0.01</damping>
          <friction>0.2</friction>
          <spring_reference>0</spring_reference>
          <spring_stiffness>0</spring_stiffness>
        </dynamics>
        <use_parent_model_frame>1</use_parent_model_frame>
      </axis>
    </joint>
    <link name='RL_hip'>
      <pose frame=''>-0.1934 0.0465 0 0 -0 0</pose>
      <inertial>
        <pose frame=''>0.0054 0.00194 -0.000105 0 -0 0</pose>
        <mass>0.678</mass>
        <inertia>
          <ixx>0.00048</ixx>
          <ixy>3.01e-06</ixy>
          <ixz>-1.11e-06</ixz>
          <iyy>0.000884</iyy>
          <iyz>-1.42e-06</iyz>
          <izz>0.000596</izz>
        </inertia>
      </inertial>
      <collision name='RL_hip_collision'>
        <pose frame=''>0 0.0955 0 1.5708 -0 0</pose>
        <geometry>
          <cylinder>
            <length>0.04</length>
            <radius>0.046</radius>
          </cylinder>
        </geometry>
        <surface>
          <contact>
            <ode/>
          </contact>
          <friction>
            <ode>
              <mu>0.2</mu>
              <mu2>0.2</mu2>
            </ode>
          </friction>
        </surface>
      </collision>
      <visual name='RL_hip_visual'>
        <pose frame=''>0 0 0 3.14159 0 3.14159</pose>
        <geometry>
          <mesh>
            <scale>1 1 1</scale>
            <uri>model://go2_description/meshes/hip.dae</uri>
          </mesh>
        </geometry>
        <material>
          <script>
            <uri>__default__</uri>
            <name>__default__</name>
          </script>
        </material>
      </visual>
      <gravity>1</gravity>
      <velocity_decay/>
    </link>
    <joint name='RL_hip_joint' type='revolute'>
      <child>RL_hip</child>
      <parent>base</parent>
      <axis>
        <xyz>1 0 0</xyz>
        <limit>
          <lower>-1.0472</lower>
          <upper>1.0472</upper>
          <effort>23.7</effort>
          <velocity>30.1</velocity>
        </limit>
        <dynamics>
          <damping>0.01</damping>
          <friction>0.2</friction>
          <spring_reference>0</spring_reference>
          <spring_stiffness>0</spring_stiffness>
        </dynamics>
        <use_parent_model_frame>1</use_parent_model_frame>
      </axis>
    </joint>
    <link name='RL_thigh'>
      <pose frame=''>-0.1934 0.142 0 0 -0 0</pose>
      <inertial>
        <pose frame=''>-0.00374 -0.0223 -0.0327 0 -0 0</pose>
        <mass>1.152</mass>
        <inertia>
          <ixx>0.00584</ixx>
          <ixy>8.72e-05</ixy>
          <ixz>-0.000289</ixz>
          <iyy>0.0058</iyy>
          <iyz>0.000808</iyz>
          <izz>0.00103</izz>
        </inertia>
      </inertial>
      <collision name='RL_thigh_collision'>
        <pose frame=''>0 0 -0.1065 3.14159 1.57079 3.14159</pose>
        <geometry>
          <box>
            <size>0.213 0.0245 0.034</size>
          </box>
        </geometry>
        <surface>
          <contact>
            <ode>
              <kp>1e+06</kp>
              <kd>1</kd>
            </ode>
          </contact>
          <friction>
            <ode>
              <mu>0.2</mu>
              <mu2>0.2</mu2>
            </ode>
          </friction>
        </surface>
      </collision>
      <visual name='RL_thigh_visual'>
        <pose frame=''>0 0 0 0 -0 0</pose>
        <geometry>
          <mesh>
            <scale>1 1 1</scale>
            <uri>model://go2_description/meshes/thigh.dae</uri>
          </mesh>
        </geometry>
        <material>
          <script>
            <uri>__default__</uri>
            <name>__default__</name>
          </script>
        </material>
      </visual>
      <gravity>1</gravity>
      <velocity_decay/>
      <self_collide>1</self_collide>
    </link>
    <joint name='RL_thigh_joint' type='revolute'>
      <child>RL_thigh</child>
      <parent>RL_hip</parent>
      <axis>
        <xyz>0 1 0</xyz>
        <limit>
          <lower>-1.5708</lower>
          <upper>3.4907</upper>
          <effort>23.7</effort>
          <velocity>30.1</velocity>
        </limit>
        <dynamics>
          <damping>0.01</damping>
          <friction>0.2</friction>
          <spring_reference>0</spring_reference>
          <spring_stiffness>0</spring_stiffness>
        </dynamics>
        <use_parent_model_frame>1</use_parent_model_frame>
      </axis>
    </joint>
    <link name='RL_calf'>
      <pose frame=''>-0.1934 0.142 -0.213 0 -0 0</pose>
      <inertial>
        <pose frame=''>0.003944 -0.000702 -0.142477 0 -0 0</pose>
        <mass>0.214</mass>
        <inertia>
          <ixx>0.00150432</ixx>
          <ixy>5.70698e-07</ixy>
          <ixz>-5.98808e-06</ixz>
          <iyy>0.00152557</iyy>
          <iyz>1.24056e-05</iyz>
          <izz>4.38377e-05</izz>
        </inertia>
      </inertial>
      <collision name='RL_calf_collision'>
        <pose frame=''>0 0 -0.1065 3.14159 1.57079 3.14159</pose>
        <geometry>
          <box>
            <size>0.213 0.016 0.016</size>
          </box>
        </geometry>
        <surface>
          <contact>
            <ode/>
          </contact>
          <friction>
            <ode>
              <mu>0.2</mu>
              <mu2>0.2</mu2>
            </ode>
          </friction>
        </surface>
      </collision>
      <collision name='RL_calf_fixed_joint_lump__RL_foot_collision_1'>
        <pose frame=''>0 0 -0.213 0 -0 0</pose>
        <geometry>
          <sphere>
            <radius>0.02</radius>
          </sphere>
        </geometry>
        <surface>
          <contact>
            <ode>
              <kp>1e+06</kp>
              <kd>1</kd>
            </ode>
          </contact>
          <friction>
            <ode>
              <mu>0.6</mu>
              <mu2>0.6</mu2>
            </ode>
          </friction>
        </surface>
      </collision>
      <visual name='RL_calf_visual'>
        <pose frame=''>0 0 0 0 -0 0</pose>
        <geometry>
          <mesh>
            <scale>1 1 1</scale>
            <uri>model://go2_description/meshes/calf.dae</uri>
          </mesh>
        </geometry>
        <material>
          <script>
            <uri>__default__</uri>
            <name>__default__</name>
          </script>
        </material>
      </visual>
      <visual name='RL_calf_fixed_joint_lump__RL_foot_visual_1'>
        <pose frame=''>0 0 -0.213 0 -0 0</pose>
        <geometry>
          <sphere>
            <radius>0.01</radius>
          </sphere>
        </geometry>
        <plugin name='drawForcePlugin' filename='libunitreeDrawForcePlugin.so'>
          <topicName>RL_foot_contact</topicName>
        </plugin>
        <material>
          <script>
            <uri>__default__</uri>
            <name>__default__</name>
          </script>
        </material>
      </visual>
      <velocity_decay/>
      <sensor name='RL_foot_contact' type='contact'>
        <update_rate>100</update_rate>
        <plugin name='contactPlugin' filename='libunitreeFootContactPlugin.so'/>
        <contact>
          <collision>RL_calf_fixed_joint_lump__RL_foot_collision_1</collision>
          <topic>__default_topic__</topic>
        </contact>
      </sensor>
      <velocity_decay/>
      <self_collide>1</self_collide>
      <velocity_decay/>
      <gravity>1</gravity>
      <velocity_decay/>
      <self_collide>1</self_collide>
    </link>
    <joint name='RL_calf_joint' type='revolute'>
      <child>RL_calf</child>
      <parent>RL_thigh</parent>
      <axis>
        <xyz>0 1 0</xyz>
        <limit>
          <lower>-2.7227</lower>
          <upper>-0.83776</upper>
          <effort>35.55</effort>
          <velocity>20.06</velocity>
        </limit>
        <dynamics>
          <damping>0.01</damping>
          <friction>0.2</friction>
          <spring_reference>0</spring_reference>
          <spring_stiffness>0</spring_stiffness>
        </dynamics>
        <use_parent_model_frame>1</use_parent_model_frame>
      </axis>
    </joint>
    <link name='RR_hip'>
      <pose frame=''>-0.1934 -0.0465 0 0 -0 0</pose>
      <inertial>
        <pose frame=''>0.0054 -0.00194 -0.000105 0 -0 0</pose>
        <mass>0.678</mass>
        <inertia>
          <ixx>0.00048</ixx>
          <ixy>-3.01e-06</ixy>
          <ixz>-1.11e-06</ixz>
          <iyy>0.000884</iyy>
          <iyz>1.42e-06</iyz>
          <izz>0.000596</izz>
        </inertia>
      </inertial>
      <collision name='RR_hip_collision'>
        <pose frame=''>0 -0.0955 0 1.5708 -0 0</pose>
        <geometry>
          <cylinder>
            <length>0.04</length>
            <radius>0.046</radius>
          </cylinder>
        </geometry>
        <surface>
          <contact>
            <ode/>
          </contact>
          <friction>
            <ode>
              <mu>0.2</mu>
              <mu2>0.2</mu2>
            </ode>
          </friction>
        </surface>
      </collision>
      <visual name='RR_hip_visual'>
        <pose frame=''>0 0 0 -0 0 3.14159</pose>
        <geometry>
          <mesh>
            <scale>1 1 1</scale>
            <uri>model://go2_description/meshes/hip.dae</uri>
          </mesh>
        </geometry>
        <material>
          <script>
            <uri>__default__</uri>
            <name>__default__</name>
          </script>
        </material>
      </visual>
      <gravity>1</gravity>
      <velocity_decay/>
    </link>
    <joint name='RR_hip_joint' type='revolute'>
      <child>RR_hip</child>
      <parent>base</parent>
      <axis>
        <xyz>1 0 0</xyz>
        <limit>
          <lower>-1.0472</lower>
          <upper>1.0472</upper>
          <effort>23.7</effort>
          <velocity>30.1</velocity>
        </limit>
        <dynamics>
          <damping>0.01</damping>
          <friction>0.2</friction>
          <spring_reference>0</spring_reference>
          <spring_stiffness>0</spring_stiffness>
        </dynamics>
        <use_parent_model_frame>1</use_parent_model_frame>
      </axis>
    </joint>
    <link name='RR_thigh'>
      <pose frame=''>-0.1934 -0.142 0 0 -0 0</pose>
      <inertial>
        <pose frame=''>-0.00374 0.0223 -0.0327 0 -0 0</pose>
        <mass>1.152</mass>
        <inertia>
          <ixx>0.00584</ixx>
          <ixy>-8.72e-05</ixy>
          <ixz>-0.000289</ixz>
          <iyy>0.0058</iyy>
          <iyz>-0.000808</iyz>
          <izz>0.00103</izz>
        </inertia>
      </inertial>
      <collision name='RR_thigh_collision'>
        <pose frame=''>0 0 -0.1065 3.14159 1.57079 3.14159</pose>
        <geometry>
          <box>
            <size>0.213 0.0245 0.034</size>
          </box>
        </geometry>
        <surface>
          <contact>
            <ode>
              <kp>1e+06</kp>
              <kd>1</kd>
            </ode>
          </contact>
          <friction>
            <ode>
              <mu>0.2</mu>
              <mu2>0.2</mu2>
            </ode>
          </friction>
        </surface>
      </collision>
      <visual name='RR_thigh_visual'>
        <pose frame=''>0 0 0 0 -0 0</pose>
        <geometry>
          <mesh>
            <scale>1 1 1</scale>
            <uri>model://go2_description/meshes/thigh_mirror.dae</uri>
          </mesh>
        </geometry>
        <material>
          <script>
            <uri>__default__</uri>
            <name>__default__</name>
          </script>
        </material>
      </visual>
      <gravity>1</gravity>
      <velocity_decay/>
      <self_collide>1</self_collide>
    </link>
    <joint name='RR_thigh_joint' type='revolute'>
      <child>RR_thigh</child>
      <parent>RR_hip</parent>
      <axis>
        <xyz>0 1 0</xyz>
        <limit>
          <lower>-1.5708</lower>
          <upper>3.4907</upper>
          <effort>23.7</effort>
          <velocity>30.1</velocity>
        </limit>
        <dynamics>
          <damping>0.01</damping>
          <friction>0.2</friction>
          <spring_reference>0</spring_reference>
          <spring_stiffness>0</spring_stiffness>
        </dynamics>
        <use_parent_model_frame>1</use_parent_model_frame>
      </axis>
    </joint>
    <link name='RR_calf'>
      <pose frame=''>-0.1934 -0.142 -0.213 0 -0 0</pose>
      <inertial>
        <pose frame=''>0.003944 -0.000702 -0.142477 0 -0 0</pose>
        <mass>0.214</mass>
        <inertia>
          <ixx>0.00150432</ixx>
          <ixy>5.70698e-07</ixy>
          <ixz>-5.98808e-06</ixz>
          <iyy>0.00152557</iyy>
          <iyz>1.24056e-05</iyz>
          <izz>4.38377e-05</izz>
        </inertia>
      </inertial>
      <collision name='RR_calf_collision'>
        <pose frame=''>0 0 -0.1065 3.14159 1.57079 3.14159</pose>
        <geometry>
          <box>
            <size>0.213 0.016 0.016</size>
          </box>
        </geometry>
        <surface>
          <contact>
            <ode/>
          </contact>
          <friction>
            <ode>
              <mu>0.2</mu>
              <mu2>0.2</mu2>
            </ode>
          </friction>
        </surface>
      </collision>
      <collision name='RR_calf_fixed_joint_lump__RR_foot_collision_1'>
        <pose frame=''>0 0 -0.213 0 -0 0</pose>
        <geometry>
          <sphere>
            <radius>0.02</radius>
          </sphere>
        </geometry>
        <surface>
          <contact>
            <ode>
              <kp>1e+06</kp>
              <kd>1</kd>
            </ode>
          </contact>
          <friction>
            <ode>
              <mu>0.6</mu>
              <mu2>0.6</mu2>
            </ode>
          </friction>
        </surface>
      </collision>
      <visual name='RR_calf_visual'>
        <pose frame=''>0 0 0 0 -0 0</pose>
        <geometry>
          <mesh>
            <scale>1 1 1</scale>
            <uri>model://go2_description/meshes/calf.dae</uri>
          </mesh>
        </geometry>
        <material>
          <script>
            <uri>__default__</uri>
            <name>__default__</name>
          </script>
        </material>
      </visual>
      <visual name='RR_calf_fixed_joint_lump__RR_foot_visual_1'>
        <pose frame=''>0 0 -0.213 0 -0 0</pose>
        <geometry>
          <sphere>
            <radius>0.01</radius>
          </sphere>
        </geometry>
        <plugin name='drawForcePlugin' filename='libunitreeDrawForcePlugin.so'>
          <topicName>RR_foot_contact</topicName>
        </plugin>
        <material>
          <script>
            <uri>__default__</uri>
            <name>__default__</name>
          </script>
        </material>
      </visual>
      <velocity_decay/>
      <sensor name='RR_foot_contact' type='contact'>
        <update_rate>100</update_rate>
        <plugin name='contactPlugin' filename='libunitreeFootContactPlugin.so'/>
        <contact>
          <collision>RR_calf_fixed_joint_lump__RR_foot_collision_1</collision>
          <topic>__default_topic__</topic>
        </contact>
      </sensor>
      <velocity_decay/>
      <self_collide>1</self_collide>
      <velocity_decay/>
      <gravity>1</gravity>
      <velocity_decay/>
      <self_collide>1</self_collide>
    </link>
    <joint name='RR_calf_joint' type='revolute'>
      <child>RR_calf</child>
      <parent>RR_thigh</parent>
      <axis>
        <xyz>0 1 0</xyz>
        <limit>
          <lower>-2.7227</lower>
          <upper>-0.83776</upper>
          <effort>35.55</effort>
          <velocity>20.06</velocity>
        </limit>
        <dynamics>
          <damping>0.01</damping>
          <friction>0.2</friction>
          <spring_reference>0</spring_reference>
          <spring_stiffness>0</spring_stiffness>
        </dynamics>
        <use_parent_model_frame>1</use_parent_model_frame>
      </axis>
    </joint>
    <plugin name='gazebo_ros_control' filename='libgazebo_ros_control.so'/>
    <static>0</static>
    <plugin name='gazebo_ros_force' filename='libgazebo_ros_force.so'>
      <topicName>/apply_force/trunk</topicName>
      <bodyName>base</bodyName>
      <xyzOffset>0 0 0</xyzOffset>
      <rpyOffset>0 -0 0</rpyOffset>
    </plugin>
  </model>
</sdf>
